2025-08-09 12:00:33,576 - INFO - PlanExecutor initialized with plan: plan.json
2025-08-09 12:00:33,576 - INFO - Working directory: \app
2025-08-09 12:00:33,576 - INFO - Loading and validating plan...
2025-08-09 12:00:33,577 - INFO - Plan validation completed successfully
2025-08-09 12:00:33,577 - INFO - Starting data sourcing phase...
2025-08-09 12:00:33,577 - INFO - Processing data source 1/2
2025-08-09 12:00:33,577 - INFO - Description: Scrape the list of highest grossing films from Wikipedia
2025-08-09 12:00:33,577 - INFO - Executing source_0 (attempt 1/4)
2025-08-09 12:00:33,577 - INFO - Generating code using Anthropic LLM...
2025-08-09 12:00:40,503 - INFO - HTTP Request: POST https://api.anthropic.com/v1/messages "HTTP/1.1 200 OK"
2025-08-09 12:00:40,543 - INFO - Executing code in Docker container...
2025-08-09 12:00:46,938 - WARNING - Attempt 1 failed: Traceback (most recent call last):
  File "/usr/local/lib/python3.11/site-packages/pandas/core/indexes/base.py", line 3812, in get_loc
    return self._engine.get_loc(casted_key)
           ^^^^^^^^^^^^^^^^^^^^^^^^^^^^^^^^
  File "pandas/_libs/index.pyx", line 167, in pandas._libs.index.IndexEngine.get_loc
  File "pandas/_libs/index.pyx", line 196, in pandas._libs.index.IndexEngine.get_loc
  File "pandas/_libs/hashtable_class_helper.pxi", line 7088, in pandas._libs.hashtable.PyObjectHashTable.get_item
  File "pandas/_libs/hashtable_class_helper.pxi", line 7096, in pandas._libs.hashtable.PyObjectHashTable.get_item
KeyError: 'Worldwide gross'

The above exception was the direct cause of the following exception:

Traceback (most recent call last):
  File "/app/script.py", line 52, in <module>
    print(len(df[(df["Worldwide gross"] >= 2_000_000_000) & (df["Year"] < 2000)]))
                  ~~^^^^^^^^^^^^^^^^^^^
  File "/usr/local/lib/python3.11/site-packages/pandas/core/frame.py", line 4107, in __getitem__
    indexer = self.columns.get_loc(key)
              ^^^^^^^^^^^^^^^^^^^^^^^^^
  File "/usr/local/lib/python3.11/site-packages/pandas/core/indexes/base.py", line 3819, in get_loc
    raise KeyError(key) from err
KeyError: 'Worldwide gross'

2025-08-09 12:00:47,940 - INFO - Executing source_0 (attempt 2/4)
2025-08-09 12:00:47,941 - INFO - Generating code using Anthropic LLM...
2025-08-09 12:00:54,733 - INFO - HTTP Request: POST https://api.anthropic.com/v1/messages "HTTP/1.1 200 OK"
2025-08-09 12:00:54,735 - INFO - Executing code in Docker container...
2025-08-09 12:01:00,100 - WARNING - Attempt 2 failed: Traceback (most recent call last):
  File "/usr/local/lib/python3.11/site-packages/pandas/core/indexes/base.py", line 3812, in get_loc
    return self._engine.get_loc(casted_key)
           ^^^^^^^^^^^^^^^^^^^^^^^^^^^^^^^^
  File "pandas/_libs/index.pyx", line 167, in pandas._libs.index.IndexEngine.get_loc
  File "pandas/_libs/index.pyx", line 196, in pandas._libs.index.IndexEngine.get_loc
  File "pandas/_libs/hashtable_class_helper.pxi", line 7088, in pandas._libs.hashtable.PyObjectHashTable.get_item
  File "pandas/_libs/hashtable_class_helper.pxi", line 7096, in pandas._libs.hashtable.PyObjectHashTable.get_item
KeyError: 'Rank'

The above exception was the direct cause of the following exception:

Traceback (most recent call last):
  File "/app/script.py", line 23, in <module>
    df["Rank"] = df["Rank"].astype("int64")
                 ~~^^^^^^^^
  File "/usr/local/lib/python3.11/site-packages/pandas/core/frame.py", line 4107, in __getitem__
    indexer = self.columns.get_loc(key)
              ^^^^^^^^^^^^^^^^^^^^^^^^^
  File "/usr/local/lib/python3.11/site-packages/pandas/core/indexes/base.py", line 3819, in get_loc
    raise KeyError(key) from err
KeyError: 'Rank'

2025-08-09 12:01:02,102 - INFO - Executing source_0 (attempt 3/4)
2025-08-09 12:01:02,103 - INFO - Generating code using Anthropic LLM...
2025-08-09 12:01:08,765 - INFO - HTTP Request: POST https://api.anthropic.com/v1/messages "HTTP/1.1 200 OK"
2025-08-09 12:01:08,767 - INFO - Executing code in Docker container...
2025-08-09 12:01:14,407 - WARNING - Attempt 3 failed: Traceback (most recent call last):
  File "/usr/local/lib/python3.11/site-packages/pandas/core/indexes/base.py", line 3812, in get_loc
    return self._engine.get_loc(casted_key)
           ^^^^^^^^^^^^^^^^^^^^^^^^^^^^^^^^
  File "pandas/_libs/index.pyx", line 167, in pandas._libs.index.IndexEngine.get_loc
  File "pandas/_libs/index.pyx", line 196, in pandas._libs.index.IndexEngine.get_loc
  File "pandas/_libs/hashtable_class_helper.pxi", line 7088, in pandas._libs.hashtable.PyObjectHashTable.get_item
  File "pandas/_libs/hashtable_class_helper.pxi", line 7096, in pandas._libs.hashtable.PyObjectHashTable.get_item
KeyError: 'Rank'

The above exception was the direct cause of the following exception:

Traceback (most recent call last):
  File "/app/script.py", line 23, in <module>
    df["Rank"] = df["Rank"].astype("int64")
                 ~~^^^^^^^^
  File "/usr/local/lib/python3.11/site-packages/pandas/core/frame.py", line 4107, in __getitem__
    indexer = self.columns.get_loc(key)
              ^^^^^^^^^^^^^^^^^^^^^^^^^
  File "/usr/local/lib/python3.11/site-packages/pandas/core/indexes/base.py", line 3819, in get_loc
    raise KeyError(key) from err
KeyError: 'Rank'

2025-08-09 12:01:18,411 - INFO - Executing source_0 (attempt 4/4)
2025-08-09 12:01:18,412 - INFO - Generating code using Anthropic LLM...
2025-08-09 12:01:24,431 - INFO - HTTP Request: POST https://api.anthropic.com/v1/messages "HTTP/1.1 200 OK"
2025-08-09 12:01:24,459 - INFO - Executing code in Docker container...
2025-08-09 12:01:31,173 - WARNING - Attempt 4 failed: Traceback (most recent call last):
  File "/usr/local/lib/python3.11/site-packages/pandas/core/indexes/base.py", line 3812, in get_loc
    return self._engine.get_loc(casted_key)
           ^^^^^^^^^^^^^^^^^^^^^^^^^^^^^^^^
  File "pandas/_libs/index.pyx", line 167, in pandas._libs.index.IndexEngine.get_loc
  File "pandas/_libs/index.pyx", line 196, in pandas._libs.index.IndexEngine.get_loc
  File "pandas/_libs/hashtable_class_helper.pxi", line 7088, in pandas._libs.hashtable.PyObjectHashTable.get_item
  File "pandas/_libs/hashtable_class_helper.pxi", line 7096, in pandas._libs.hashtable.PyObjectHashTable.get_item
KeyError: 'Rank'

The above exception was the direct cause of the following exception:

Traceback (most recent call last):
  File "/app/script.py", line 23, in <module>
    df["Rank"] = df["Rank"].astype("int64")
                 ~~^^^^^^^^
  File "/usr/local/lib/python3.11/site-packages/pandas/core/frame.py", line 4107, in __getitem__
    indexer = self.columns.get_loc(key)
              ^^^^^^^^^^^^^^^^^^^^^^^^^
  File "/usr/local/lib/python3.11/site-packages/pandas/core/indexes/base.py", line 3819, in get_loc
    raise KeyError(key) from err
KeyError: 'Rank'

2025-08-09 12:01:31,182 - ERROR - Plan execution failed: Critical failure in data sourcing: All retry attempts failed. Final error: Traceback (most recent call last):
  File "/usr/local/lib/python3.11/site-packages/pandas/core/indexes/base.py", line 3812, in get_loc
    return self._engine.get_loc(casted_key)
           ^^^^^^^^^^^^^^^^^^^^^^^^^^^^^^^^
  File "pandas/_libs/index.pyx", line 167, in pandas._libs.index.IndexEngine.get_loc
  File "pandas/_libs/index.pyx", line 196, in pandas._libs.index.IndexEngine.get_loc
  File "pandas/_libs/hashtable_class_helper.pxi", line 7088, in pandas._libs.hashtable.PyObjectHashTable.get_item
  File "pandas/_libs/hashtable_class_helper.pxi", line 7096, in pandas._libs.hashtable.PyObjectHashTable.get_item
KeyError: 'Rank'

The above exception was the direct cause of the following exception:

Traceback (most recent call last):
  File "/app/script.py", line 23, in <module>
    df["Rank"] = df["Rank"].astype("int64")
                 ~~^^^^^^^^
  File "/usr/local/lib/python3.11/site-packages/pandas/core/frame.py", line 4107, in __getitem__
    indexer = self.columns.get_loc(key)
              ^^^^^^^^^^^^^^^^^^^^^^^^^
  File "/usr/local/lib/python3.11/site-packages/pandas/core/indexes/base.py", line 3819, in get_loc
    raise KeyError(key) from err
KeyError: 'Rank'

2025-08-09 12:01:31,183 - ERROR - Traceback (most recent call last):
  File "E:\BS\Sem_May_2025\TDS\_PROJECT_2\final2\execute_plan.py", line 535, in execute_plan
    sourcing_result = self.execute_sourcing_plan()
  File "E:\BS\Sem_May_2025\TDS\_PROJECT_2\final2\execute_plan.py", line 315, in execute_sourcing_plan
    raise PlanExecutionError(f"Critical failure in data sourcing: {result}")
PlanExecutionError: Critical failure in data sourcing: All retry attempts failed. Final error: Traceback (most recent call last):
  File "/usr/local/lib/python3.11/site-packages/pandas/core/indexes/base.py", line 3812, in get_loc
    return self._engine.get_loc(casted_key)
           ^^^^^^^^^^^^^^^^^^^^^^^^^^^^^^^^
  File "pandas/_libs/index.pyx", line 167, in pandas._libs.index.IndexEngine.get_loc
  File "pandas/_libs/index.pyx", line 196, in pandas._libs.index.IndexEngine.get_loc
  File "pandas/_libs/hashtable_class_helper.pxi", line 7088, in pandas._libs.hashtable.PyObjectHashTable.get_item
  File "pandas/_libs/hashtable_class_helper.pxi", line 7096, in pandas._libs.hashtable.PyObjectHashTable.get_item
KeyError: 'Rank'

The above exception was the direct cause of the following exception:

Traceback (most recent call last):
  File "/app/script.py", line 23, in <module>
    df["Rank"] = df["Rank"].astype("int64")
                 ~~^^^^^^^^
  File "/usr/local/lib/python3.11/site-packages/pandas/core/frame.py", line 4107, in __getitem__
    indexer = self.columns.get_loc(key)
              ^^^^^^^^^^^^^^^^^^^^^^^^^
  File "/usr/local/lib/python3.11/site-packages/pandas/core/indexes/base.py", line 3819, in get_loc
    raise KeyError(key) from err
KeyError: 'Rank'


2025-08-09 12:01:31,183 - ERROR - Plan execution error: Plan execution failed: Critical failure in data sourcing: All retry attempts failed. Final error: Traceback (most recent call last):
  File "/usr/local/lib/python3.11/site-packages/pandas/core/indexes/base.py", line 3812, in get_loc
    return self._engine.get_loc(casted_key)
           ^^^^^^^^^^^^^^^^^^^^^^^^^^^^^^^^
  File "pandas/_libs/index.pyx", line 167, in pandas._libs.index.IndexEngine.get_loc
  File "pandas/_libs/index.pyx", line 196, in pandas._libs.index.IndexEngine.get_loc
  File "pandas/_libs/hashtable_class_helper.pxi", line 7088, in pandas._libs.hashtable.PyObjectHashTable.get_item
  File "pandas/_libs/hashtable_class_helper.pxi", line 7096, in pandas._libs.hashtable.PyObjectHashTable.get_item
KeyError: 'Rank'

The above exception was the direct cause of the following exception:

Traceback (most recent call last):
  File "/app/script.py", line 23, in <module>
    df["Rank"] = df["Rank"].astype("int64")
                 ~~^^^^^^^^
  File "/usr/local/lib/python3.11/site-packages/pandas/core/frame.py", line 4107, in __getitem__
    indexer = self.columns.get_loc(key)
              ^^^^^^^^^^^^^^^^^^^^^^^^^
  File "/usr/local/lib/python3.11/site-packages/pandas/core/indexes/base.py", line 3819, in get_loc
    raise KeyError(key) from err
KeyError: 'Rank'

2025-08-09 12:06:53,926 - INFO - PlanExecutor initialized with plan: plan.json
2025-08-09 12:06:53,927 - INFO - Working directory: \app
2025-08-09 12:06:53,927 - INFO - Loading and validating plan...
2025-08-09 12:06:53,927 - ERROR - Plan execution failed: Error loading plan: Analysis task 0: missing required field 'task_id'
2025-08-09 12:06:53,929 - ERROR - Traceback (most recent call last):
  File "E:\BS\Sem_May_2025\TDS\_PROJECT_2\final2\execute_plan.py", line 98, in load_and_validate_plan
    self._validate_analysis_task(task, i)
    ~~~~~~~~~~~~~~~~~~~~~~~~~~~~^^^^^^^^^
  File "E:\BS\Sem_May_2025\TDS\_PROJECT_2\final2\execute_plan.py", line 132, in _validate_analysis_task
    raise PlanExecutionError(f"Analysis task {index}: missing required field '{field}'")
PlanExecutionError: Analysis task 0: missing required field 'task_id'

During handling of the above exception, another exception occurred:

Traceback (most recent call last):
  File "E:\BS\Sem_May_2025\TDS\_PROJECT_2\final2\execute_plan.py", line 532, in execute_plan
    self.plan_data = self.load_and_validate_plan()
                     ~~~~~~~~~~~~~~~~~~~~~~~~~~~^^
  File "E:\BS\Sem_May_2025\TDS\_PROJECT_2\final2\execute_plan.py", line 108, in load_and_validate_plan
    raise PlanExecutionError(f"Error loading plan: {e}")
PlanExecutionError: Error loading plan: Analysis task 0: missing required field 'task_id'

2025-08-09 12:06:53,929 - ERROR - Plan execution error: Plan execution failed: Error loading plan: Analysis task 0: missing required field 'task_id'
2025-08-09 12:09:28,105 - INFO - PlanExecutor initialized with plan: plan.json
2025-08-09 12:09:28,106 - INFO - Working directory: \app
2025-08-09 12:09:28,106 - INFO - Loading and validating plan...
2025-08-09 12:09:28,106 - INFO - Plan validation completed successfully
2025-08-09 12:09:28,107 - INFO - Starting data sourcing phase...
2025-08-09 12:09:28,107 - INFO - Processing data source 1/1
2025-08-09 12:09:28,107 - INFO - Description: Scrape the list of highest grossing films from Wikipedia.
2025-08-09 12:09:28,107 - INFO - Executing source_0 (attempt 1/4)
2025-08-09 12:09:28,107 - INFO - Generating code using Anthropic LLM...
2025-08-09 12:09:31,769 - INFO - HTTP Request: POST https://api.anthropic.com/v1/messages "HTTP/1.1 200 OK"
2025-08-09 12:09:31,781 - INFO - Executing code in Docker container...
2025-08-09 12:09:37,835 - WARNING - Attempt 1 failed: /app/script.py:21: FutureWarning: Passing literal html to 'read_html' is deprecated and will be removed in a future version. To read from a literal string, wrap it in a 'StringIO' object.
  data = pd.read_html(str(table))[0]
Traceback (most recent call last):
  File "/app/script.py", line 41, in <module>
    highest_grossing_films = scrape_highest_grossing_films()
                             ^^^^^^^^^^^^^^^^^^^^^^^^^^^^^^^
  File "/app/script.py", line 38, in scrape_highest_grossing_films
    raise e
  File "/app/script.py", line 28, in scrape_highest_grossing_films
    data.columns = ["Rank", "Title", "Worldwide gross", "Year", "Ref"]
    ^^^^^^^^^^^^
  File "/usr/local/lib/python3.11/site-packages/pandas/core/generic.py", line 6332, in __setattr__
    return object.__setattr__(self, name, value)
           ^^^^^^^^^^^^^^^^^^^^^^^^^^^^^^^^^^^^^
  File "pandas/_libs/properties.pyx", line 69, in pandas._libs.properties.AxisProperty.__set__
  File "/usr/local/lib/python3.11/site-packages/pandas/core/generic.py", line 814, in _set_axis
    self._mgr.set_axis(axis, labels)
  File "/usr/local/lib/python3.11/site-packages/pandas/core/internals/managers.py", line 238, in set_axis
    self._validate_set_axis(axis, new_labels)
  File "/usr/local/lib/python3.11/site-packages/pandas/core/internals/base.py", line 98, in _validate_set_axis
    raise ValueError(
ValueError: Length mismatch: Expected axis has 6 elements, new values have 5 elements

2025-08-09 12:09:38,837 - INFO - Executing source_0 (attempt 2/4)
2025-08-09 12:09:38,838 - INFO - Generating code using Anthropic LLM...
2025-08-09 12:09:42,410 - INFO - HTTP Request: POST https://api.anthropic.com/v1/messages "HTTP/1.1 200 OK"
2025-08-09 12:09:42,412 - INFO - Executing code in Docker container...
2025-08-09 12:09:46,652 - INFO - Data sourcing completed. Available variables: ['highest_grossing_films']
2025-08-09 12:09:46,653 - INFO - Starting data analysis phase...
2025-08-09 12:09:46,659 - INFO - Processing analysis task 1: q1_How many $2 bn movies were released before 2000?
2025-08-09 12:09:46,663 - INFO - Instruction: Filter the dataframe to find movies with a worldwide gross greater than $2 billion and released before the year 2000. Then, count the number of movies that meet these criteria.
2025-08-09 12:09:46,684 - INFO - Executing q1_How many $2 bn movies were released before 2000? (attempt 1/4)
2025-08-09 12:09:46,688 - INFO - Generating code using Anthropic LLM...
2025-08-09 12:09:48,654 - INFO - HTTP Request: POST https://api.anthropic.com/v1/messages "HTTP/1.1 200 OK"
2025-08-09 12:09:48,657 - INFO - Executing code in Docker container...
2025-08-09 12:09:50,031 - WARNING - Attempt 1 failed:   File "/app/script.py", line 15
    return num_movies
    ^^^^^^^^^^^^^^^^^
SyntaxError: 'return' outside function

2025-08-09 12:09:51,033 - INFO - Executing q1_How many $2 bn movies were released before 2000? (attempt 2/4)
2025-08-09 12:09:51,034 - INFO - Generating code using Anthropic LLM...
2025-08-09 12:09:53,411 - INFO - HTTP Request: POST https://api.anthropic.com/v1/messages "HTTP/1.1 200 OK"
2025-08-09 12:09:53,412 - INFO - Executing code in Docker container...
2025-08-09 12:09:54,928 - WARNING - Attempt 2 failed:   File "/app/script.py", line 15
    return num_movies
    ^^^^^^^^^^^^^^^^^
SyntaxError: 'return' outside function

2025-08-09 12:09:56,930 - INFO - Executing q1_How many $2 bn movies were released before 2000? (attempt 3/4)
2025-08-09 12:09:56,930 - INFO - Generating code using Anthropic LLM...
2025-08-09 12:09:59,903 - INFO - HTTP Request: POST https://api.anthropic.com/v1/messages "HTTP/1.1 200 OK"
2025-08-09 12:09:59,905 - INFO - Executing code in Docker container...
2025-08-09 12:10:02,628 - WARNING - Attempt 3 failed: Traceback (most recent call last):
  File "/app/script.py", line 25, in <module>
    num_2bn_movies_before_2000 = get_num_2bn_movies_before_2000(highest_grossing_films)
                                                                ^^^^^^^^^^^^^^^^^^^^^^
NameError: name 'highest_grossing_films' is not defined

2025-08-09 12:10:06,629 - INFO - Executing q1_How many $2 bn movies were released before 2000? (attempt 4/4)
2025-08-09 12:10:06,630 - INFO - Generating code using Anthropic LLM...
2025-08-09 12:10:09,543 - INFO - HTTP Request: POST https://api.anthropic.com/v1/messages "HTTP/1.1 200 OK"
2025-08-09 12:10:09,545 - INFO - Executing code in Docker container...
2025-08-09 12:10:12,404 - WARNING - Attempt 4 failed: Traceback (most recent call last):
  File "/app/script.py", line 25, in <module>
    num_2bn_movies_before_2000 = get_num_2bn_movies_before_2000(highest_grossing_films)
                                                                ^^^^^^^^^^^^^^^^^^^^^^
NameError: name 'highest_grossing_films' is not defined

2025-08-09 12:10:12,448 - INFO - Processing analysis task 2: q2_Which is the earliest film that grossed over $1.5 bn?
2025-08-09 12:10:12,449 - INFO - Instruction: Convert 'Worldwide gross' column to numeric. Filter the dataframe to find movies with a worldwide gross greater than $1.5 billion. Find the earliest year among these movies and return the title of the movie released in that year.
2025-08-09 12:10:12,451 - INFO - Executing q2_Which is the earliest film that grossed over $1.5 bn? (attempt 1/4)
2025-08-09 12:10:12,451 - INFO - Generating code using Anthropic LLM...
2025-08-09 12:10:14,595 - INFO - HTTP Request: POST https://api.anthropic.com/v1/messages "HTTP/1.1 200 OK"
2025-08-09 12:10:14,597 - INFO - Executing code in Docker container...
2025-08-09 12:10:16,325 - WARNING - Attempt 1 failed:   File "/app/script.py", line 19
    return earliest_movie
    ^^^^^^^^^^^^^^^^^^^^^
SyntaxError: 'return' outside function

2025-08-09 12:10:17,326 - INFO - Executing q2_Which is the earliest film that grossed over $1.5 bn? (attempt 2/4)
2025-08-09 12:10:17,327 - INFO - Generating code using Anthropic LLM...
2025-08-09 12:10:20,293 - INFO - HTTP Request: POST https://api.anthropic.com/v1/messages "HTTP/1.1 200 OK"
2025-08-09 12:10:20,294 - INFO - Executing code in Docker container...
2025-08-09 12:10:22,524 - INFO - Processing analysis task 3: q3_What's the correlation between the Rank and Peak?
2025-08-09 12:10:22,524 - INFO - Instruction: There is no 'Peak' column in the dataframe. Assuming 'Year' to calculate the correlation. Calculate the correlation between the 'Rank' and 'Year' columns in the dataframe. Return the correlation coefficient.
2025-08-09 12:10:22,524 - INFO - Executing q3_What's the correlation between the Rank and Peak? (attempt 1/4)
2025-08-09 12:10:22,525 - INFO - Generating code using Anthropic LLM...
2025-08-09 12:10:24,210 - INFO - HTTP Request: POST https://api.anthropic.com/v1/messages "HTTP/1.1 200 OK"
2025-08-09 12:10:24,212 - INFO - Executing code in Docker container...
2025-08-09 12:10:26,684 - INFO - Processing analysis task 4: q4_Draw a scatterplot of Rank and Peak along with a dotted red regression line through it.
2025-08-09 12:10:26,684 - INFO - Instruction: There is no 'Peak' column in the dataframe. Assuming 'Year' to create the scatterplot. Create a scatterplot of 'Rank' vs 'Year'. Add a regression line to the plot using seaborn's regplot. Customize the regression line to be dotted and red. Convert the plot to a base64 encoded PNG image.
2025-08-09 12:10:26,685 - INFO - Executing q4_Draw a scatterplot of Rank and Peak along with a dotted red regression line through it. (attempt 1/4)
2025-08-09 12:10:26,686 - INFO - Generating code using Anthropic LLM...
2025-08-09 12:10:29,208 - INFO - HTTP Request: POST https://api.anthropic.com/v1/messages "HTTP/1.1 200 OK"
2025-08-09 12:10:29,214 - INFO - Executing code in Docker container...
2025-08-09 12:10:33,668 - INFO - Data analysis phase completed
2025-08-09 12:10:33,668 - INFO - Plan execution completed successfully!
2025-08-09 12:10:33,668 - INFO - Final results: 4 items
2025-08-09 12:12:35,964 - INFO - PlanExecutor initialized with plan: plan.json
2025-08-09 12:12:35,965 - INFO - Working directory: \app
2025-08-09 12:12:35,965 - INFO - Loading and validating plan...
2025-08-09 12:12:35,966 - INFO - Plan validation completed successfully
2025-08-09 12:12:35,966 - INFO - Starting data sourcing phase...
2025-08-09 12:12:35,966 - INFO - Processing data source 1/1
2025-08-09 12:12:35,966 - INFO - Description: Scrape the list of highest-grossing films from Wikipedia.
2025-08-09 12:12:35,966 - INFO - Executing source_0 (attempt 1/4)
2025-08-09 12:12:35,967 - INFO - Generating code using Anthropic LLM...
2025-08-09 12:12:39,867 - INFO - HTTP Request: POST https://api.anthropic.com/v1/messages "HTTP/1.1 200 OK"
2025-08-09 12:12:39,903 - INFO - Executing code in Docker container...
2025-08-09 12:12:43,178 - WARNING - No stdout but stderr present: 2025-08-09 06:42:42,514 ERROR: Error occurred while scraping highest-grossing films: 'Rank'
2025-08-09 12:12:43,239 - INFO - Data sourcing completed. Available variables: ['highest_grossing_films_df']
2025-08-09 12:12:43,240 - INFO - Starting data analysis phase...
2025-08-09 12:12:43,241 - INFO - Processing analysis task 1: q_1_How many $2 bn movies were released before 2000?
2025-08-09 12:12:43,241 - INFO - Instruction: Clean 'Worldwide Gross' column by removing non-numeric characters ($, commas, and bracketed footnotes like [1]) and converting to float. Clean 'Year' column by removing any bracketed footnotes and converting to integer. Filter the 'highest_grossing_films_df' for films with 'Worldwide Gross' greater than or equal to 2,000,000,000 and 'Year' less than 2000. Count the number of such films.
2025-08-09 12:12:43,241 - INFO - Executing q_1_How many $2 bn movies were released before 2000? (attempt 1/4)
2025-08-09 12:12:43,241 - INFO - Generating code using Anthropic LLM...
2025-08-09 12:12:45,291 - INFO - HTTP Request: POST https://api.anthropic.com/v1/messages "HTTP/1.1 200 OK"
2025-08-09 12:12:45,292 - INFO - Executing code in Docker container...
2025-08-09 12:12:47,777 - WARNING - Attempt 1 failed: Traceback (most recent call last):
  File "/app/script.py", line 3, in <module>
    df = highest_grossing_films_df.copy()
         ^^^^^^^^^^^^^^^^^^^^^^^^^
NameError: name 'highest_grossing_films_df' is not defined

2025-08-09 12:12:48,778 - INFO - Executing q_1_How many $2 bn movies were released before 2000? (attempt 2/4)
2025-08-09 12:12:48,780 - INFO - Generating code using Anthropic LLM...
2025-08-09 12:12:51,230 - INFO - HTTP Request: POST https://api.anthropic.com/v1/messages "HTTP/1.1 200 OK"
2025-08-09 12:12:51,233 - INFO - Executing code in Docker container...
2025-08-09 12:12:53,920 - INFO - Processing analysis task 2: q_2_Which is the earliest film that grossed over $1.5 bn?
2025-08-09 12:12:53,920 - INFO - Instruction: Clean 'Worldwide Gross' column by removing non-numeric characters ($, commas, and bracketed footnotes like [1]) and converting to float. Clean 'Year' column by removing any bracketed footnotes and converting to integer. Filter the 'highest_grossing_films_df' for films with 'Worldwide Gross' greater than or equal to 1,500,000,000. From the filtered DataFrame, find the film with the minimum 'Year'. Return the 'Film' name.
2025-08-09 12:12:53,921 - INFO - Executing q_2_Which is the earliest film that grossed over $1.5 bn? (attempt 1/4)
2025-08-09 12:12:53,922 - INFO - Generating code using Anthropic LLM...
2025-08-09 12:12:56,657 - INFO - HTTP Request: POST https://api.anthropic.com/v1/messages "HTTP/1.1 200 OK"
2025-08-09 12:12:56,659 - INFO - Executing code in Docker container...
2025-08-09 12:12:59,687 - WARNING - Attempt 1 failed: Traceback (most recent call last):
  File "/app/script.py", line 3, in <module>
    df = highest_grossing_films_df.copy()
         ^^^^^^^^^^^^^^^^^^^^^^^^^
NameError: name 'highest_grossing_films_df' is not defined

2025-08-09 12:13:00,688 - INFO - Executing q_2_Which is the earliest film that grossed over $1.5 bn? (attempt 2/4)
2025-08-09 12:13:00,689 - INFO - Generating code using Anthropic LLM...
2025-08-09 12:13:04,150 - INFO - HTTP Request: POST https://api.anthropic.com/v1/messages "HTTP/1.1 200 OK"
2025-08-09 12:13:04,151 - INFO - Executing code in Docker container...
2025-08-09 12:13:06,214 - WARNING - Attempt 2 failed: 
2025-08-09 12:13:08,215 - INFO - Executing q_2_Which is the earliest film that grossed over $1.5 bn? (attempt 3/4)
2025-08-09 12:13:08,216 - INFO - Generating code using Anthropic LLM...
2025-08-09 12:13:11,813 - INFO - HTTP Request: POST https://api.anthropic.com/v1/messages "HTTP/1.1 200 OK"
2025-08-09 12:13:11,814 - INFO - Executing code in Docker container...
2025-08-09 12:13:14,707 - WARNING - Attempt 3 failed: 
2025-08-09 12:13:18,708 - INFO - Executing q_2_Which is the earliest film that grossed over $1.5 bn? (attempt 4/4)
2025-08-09 12:13:18,708 - INFO - Generating code using Anthropic LLM...
2025-08-09 12:13:22,016 - INFO - HTTP Request: POST https://api.anthropic.com/v1/messages "HTTP/1.1 200 OK"
2025-08-09 12:13:22,018 - INFO - Executing code in Docker container...
2025-08-09 12:13:24,699 - WARNING - Attempt 4 failed: 
2025-08-09 12:13:24,708 - INFO - Processing analysis task 3: q_3_What's the correlation between the Rank and Peak?
2025-08-09 12:13:24,709 - INFO - Instruction: Clean 'Rank' and 'Peak' columns by removing any bracketed footnotes (e.g., [1]) and converting to integer. Calculate the Pearson correlation coefficient between the cleaned 'Rank' and 'Peak' columns of the 'highest_grossing_films_df'.
2025-08-09 12:13:24,709 - INFO - Executing q_3_What's the correlation between the Rank and Peak? (attempt 1/4)
2025-08-09 12:13:24,710 - INFO - Generating code using Anthropic LLM...
2025-08-09 12:13:26,697 - INFO - HTTP Request: POST https://api.anthropic.com/v1/messages "HTTP/1.1 200 OK"
2025-08-09 12:13:26,699 - INFO - Executing code in Docker container...
2025-08-09 12:13:29,278 - INFO - Processing analysis task 4: q_4_Draw a scatterplot of Rank and Peak along with a dotted red regression line through it.
2025-08-09 12:13:29,279 - INFO - Instruction: Clean 'Rank' and 'Peak' columns by removing any bracketed footnotes (e.g., [1]) and converting to integer. Create a scatterplot of 'Rank' on the x-axis and 'Peak' on the y-axis using seaborn. Add a linear regression line to the plot. The regression line should be dotted and red. Set appropriate labels and title. Save the plot as a PNG image to a BytesIO object, then base64 encode it. Ensure the image size is under 100,000 bytes.
2025-08-09 12:13:29,280 - INFO - Executing q_4_Draw a scatterplot of Rank and Peak along with a dotted red regression line through it. (attempt 1/4)
2025-08-09 12:13:29,281 - INFO - Generating code using Anthropic LLM...
2025-08-09 12:13:33,932 - INFO - HTTP Request: POST https://api.anthropic.com/v1/messages "HTTP/1.1 200 OK"
2025-08-09 12:13:33,935 - INFO - Executing code in Docker container...
2025-08-09 12:13:37,773 - WARNING - Attempt 1 failed: Traceback (most recent call last):
  File "/app/script.py", line 8, in <module>
    df = highest_grossing_films_df.copy()
         ^^^^^^^^^^^^^^^^^^^^^^^^^
NameError: name 'highest_grossing_films_df' is not defined

2025-08-09 12:13:38,774 - INFO - Executing q_4_Draw a scatterplot of Rank and Peak along with a dotted red regression line through it. (attempt 2/4)
2025-08-09 12:13:38,774 - INFO - Generating code using Anthropic LLM...
2025-08-09 12:13:44,042 - INFO - HTTP Request: POST https://api.anthropic.com/v1/messages "HTTP/1.1 200 OK"
2025-08-09 12:13:44,044 - INFO - Executing code in Docker container...
2025-08-09 12:13:48,074 - WARNING - Attempt 2 failed: Traceback (most recent call last):
  File "/app/script.py", line 10, in <module>
    raise NameError("'highest_grossing_films_df' is not defined")
NameError: 'highest_grossing_films_df' is not defined

2025-08-09 12:13:50,075 - INFO - Executing q_4_Draw a scatterplot of Rank and Peak along with a dotted red regression line through it. (attempt 3/4)
2025-08-09 12:13:50,075 - INFO - Generating code using Anthropic LLM...
2025-08-09 12:13:55,162 - INFO - HTTP Request: POST https://api.anthropic.com/v1/messages "HTTP/1.1 200 OK"
2025-08-09 12:13:55,164 - INFO - Executing code in Docker container...
2025-08-09 12:13:59,699 - WARNING - Attempt 3 failed: Traceback (most recent call last):
  File "/app/script.py", line 10, in <module>
    raise NameError("'highest_grossing_films_df' is not defined")
NameError: 'highest_grossing_films_df' is not defined

2025-08-09 12:14:03,700 - INFO - Executing q_4_Draw a scatterplot of Rank and Peak along with a dotted red regression line through it. (attempt 4/4)
2025-08-09 12:14:03,700 - INFO - Generating code using Anthropic LLM...
2025-08-09 12:14:08,956 - INFO - HTTP Request: POST https://api.anthropic.com/v1/messages "HTTP/1.1 200 OK"
2025-08-09 12:14:08,959 - INFO - Executing code in Docker container...
2025-08-09 12:14:13,875 - WARNING - Attempt 4 failed: Traceback (most recent call last):
  File "/app/script.py", line 10, in <module>
    raise NameError("'highest_grossing_films_df' is not defined")
NameError: 'highest_grossing_films_df' is not defined

2025-08-09 12:14:13,878 - INFO - Data analysis phase completed
2025-08-09 12:14:13,878 - INFO - Plan execution completed successfully!
2025-08-09 12:14:13,878 - INFO - Final results: 4 items
2025-08-09 12:19:51,104 - INFO - PlanExecutor initialized with plan: plan.json
2025-08-09 12:19:51,104 - INFO - Working directory: \app
2025-08-09 12:19:51,105 - INFO - Loading plan...
2025-08-09 12:19:51,105 - INFO - Plan loaded and validated successfully
2025-08-09 12:19:51,106 - INFO - Passing full plan to Anthropic LLM...
2025-08-09 12:20:01,414 - INFO - HTTP Request: POST https://api.anthropic.com/v1/messages "HTTP/1.1 200 OK"
2025-08-09 12:20:01,437 - INFO - Executing generated script in Docker...
2025-08-09 12:20:05,195 - ERROR - Execution failed: Execution failed: Traceback (most recent call last):
  File "/app/script.py", line 18, in <module>
    raise ValueError("'studentId' column must be of type 'Int64'.")
ValueError: 'studentId' column must be of type 'Int64'.

2025-08-09 12:20:05,199 - ERROR - Traceback (most recent call last):
  File "E:\BS\Sem_May_2025\TDS\_PROJECT_2\final2\execute_full_plan.py", line 119, in execute_plan
    results = self.execute_whole_plan()
  File "E:\BS\Sem_May_2025\TDS\_PROJECT_2\final2\execute_full_plan.py", line 113, in execute_whole_plan
    raise PlanExecutionError(f"Execution failed: {stderr}")
PlanExecutionError: Execution failed: Traceback (most recent call last):
  File "/app/script.py", line 18, in <module>
    raise ValueError("'studentId' column must be of type 'Int64'.")
ValueError: 'studentId' column must be of type 'Int64'.


2025-08-09 14:26:45,000 - INFO - AFC is enabled with max remote calls: 10.
2025-08-09 14:26:51,408 - INFO - HTTP Request: POST https://generativelanguage.googleapis.com/v1beta/models/gemini-2.0-flash:generateContent "HTTP/1.1 200 OK"
2025-08-09 14:26:51,411 - INFO - AFC remote call 1 is done.
2025-08-09 14:26:51,413 - INFO - AFC is enabled with max remote calls: 10.
2025-08-09 14:27:28,216 - INFO - HTTP Request: POST https://generativelanguage.googleapis.com/v1beta/models/gemini-2.5-pro:generateContent "HTTP/1.1 200 OK"
2025-08-09 14:27:28,221 - INFO - AFC remote call 1 is done.
2025-08-09 14:27:55,862 - INFO - HTTP Request: POST https://api.anthropic.com/v1/messages "HTTP/1.1 200 OK"
2025-08-09 14:27:55,907 - INFO - Executing generated script in Docker...
2025-08-09 14:31:34,971 - INFO - AFC is enabled with max remote calls: 10.
2025-08-09 14:31:41,614 - INFO - HTTP Request: POST https://generativelanguage.googleapis.com/v1beta/models/gemini-2.0-flash:generateContent "HTTP/1.1 200 OK"
2025-08-09 14:31:41,617 - INFO - AFC remote call 1 is done.
2025-08-09 14:31:41,620 - INFO - AFC is enabled with max remote calls: 10.
2025-08-09 14:32:34,903 - INFO - HTTP Request: POST https://generativelanguage.googleapis.com/v1beta/models/gemini-2.5-pro:generateContent "HTTP/1.1 200 OK"
2025-08-09 14:32:34,907 - INFO - AFC remote call 1 is done.
2025-08-09 14:33:03,057 - INFO - HTTP Request: POST https://api.anthropic.com/v1/messages "HTTP/1.1 200 OK"
2025-08-09 14:33:03,121 - INFO - Executing generated script in Docker...
